Workbook

Sheet P&L
D1: 2022 | E1: 2022 | F1: 2022 | G1: 2023 | H1: TOTAL
D2: October | E2: November | F2: December | G2: January
B3: RM | C3: RM purchase @ std price | D3: =-'Purchases & PPV'!C17 -> -80425.5 | E3: =-'Purchases & PPV'!D17 -> -34200 | F3: =-'Purchases & PPV'!E17 -> -7300 | G3: =-'Purchases & PPV'!F17 -> -7503 | H3: =SUM(D3:G3) -> -129428.5
B4: RM | C4: PPV | D4: =-'Purchases & PPV'!C24 -> -5422 | E4: =-'Purchases & PPV'!D24 -> -1700 | F4: =-'Purchases & PPV'!E24 -> -650 | G4: =-'Purchases & PPV'!F24 -> 183 | H4: =SUM(D4:G4) -> -7589
B5: RM | C5: RM reception | D5: ='Purchases & PPV'!C17 -> 80425.5 | E5: ='Purchases & PPV'!D17 -> 34200 | F5: ='Purchases & PPV'!E17 -> 7300 | G5: ='Purchases & PPV'!F17 -> 7503 | H5: =SUM(D5:G5) -> 129428.5
A6: C | B6: RM | C6: RM consumption | D6: =SUMIFS(Movements!$K:$K,Movements!$A:$A,D$2,Movements!$G:$G,$A6,Movements!$D:$D,'P&L'!$B6) -> 0 | E6: =SUMIFS(Movements!$K:$K,Movements!$A:$A,E$2,Movements!$G:$G,$A6,Movements!$D:$D,'P&L'!$B6) -> -39852.853 | F6: =SUMIFS(Movements!$K:$K,Movements!$A:$A,F$2,Movements!$G:$G,$A6,Movements!$D:$D,'P&L'!$B6) -> -61895.887 | G6: =SUMIFS(Movements!$K:$K,Movements!$A:$A,G$2,Movements!$G:$G,$A6,Movements!$D:$D,'P&L'!$B6) -> -27801 | H6: =SUM(D6:G6) -> -129549.74
C7: consumption @ std | D7: =-'Formulation & overusage'!D106 -> 0 | E7: =-'Formulation & overusage'!E106 -> -39998.04 | F7: =-'Formulation & overusage'!F106 -> -61895.887 | G7: =-'Formulation & overusage'!G106 -> -27940.25
C8: Overusage variance | D8: =-'Formulation & overusage'!D103 -> 0 | E8: =-'Formulation & overusage'!E103 -> 180.3775 | F8: =-'Formulation & overusage'!F103 -> 55.2 | G8: =-'Formulation & overusage'!G103 -> 85.35
C9: Formulation variance | D9: =-'Formulation & overusage'!D100 -> 0 | E9: =-'Formulation & overusage'!E100 -> -35.19 | F9: =-'Formulation & overusage'!F100 -> -55.2 | G9: =-'Formulation & overusage'!G100 -> 53.9
A10: W | B10: RM | C10: RM write-off | D10: =SUMIFS(Movements!$K:$K,Movements!$A:$A,D$2,Movements!$G:$G,$A10,Movements!$D:$D,'P&L'!$B10) -> 0 | E10: =SUMIFS(Movements!$K:$K,Movements!$A:$A,E$2,Movements!$G:$G,$A10,Movements!$D:$D,'P&L'!$B10) -> -523.46 | F10: =SUMIFS(Movements!$K:$K,Movements!$A:$A,F$2,Movements!$G:$G,$A10,Movements!$D:$D,'P&L'!$B10) -> -199 | G10: =SUMIFS(Movements!$K:$K,Movements!$A:$A,G$2,Movements!$G:$G,$A10,Movements!$D:$D,'P&L'!$B10) -> -296 | H10: =SUM(D10:G10) -> -1018.46
A11: I | B11: RM | C11: RM stock adjusments | D11: =SUMIFS(Movements!$K:$K,Movements!$A:$A,D$2,Movements!$G:$G,$A11,Movements!$D:$D,'P&L'!$B11) -> 0 | E11: =SUMIFS(Movements!$K:$K,Movements!$A:$A,E$2,Movements!$G:$G,$A11,Movements!$D:$D,'P&L'!$B11) -> 0 | F11: =SUMIFS(Movements!$K:$K,Movements!$A:$A,F$2,Movements!$G:$G,$A11,Movements!$D:$D,'P&L'!$B11) -> -600 | G11: =SUMIFS(Movements!$K:$K,Movements!$A:$A,G$2,Movements!$G:$G,$A11,Movements!$D:$D,'P&L'!$B11) -> 0 | H11: =SUM(D11:G11) -> -600
B12: RM | C12: Stock reevaluation RM | D12: ='Stock reval'!E29 -> 5422 | E12: ='Stock reval'!F29 -> 767 | F12: ='Stock reval'!G29 -> -3927.7 | G12: ='Stock reval'!H29 -> -521.6 | H12: =SUM(D12:G12) -> 1739.7
A14: C | B14: SFG | C14: SFG consumption | D14: =SUMIFS(Movements!$K:$K,Movements!$A:$A,D$2,Movements!$G:$G,$A14,Movements!$D:$D,'P&L'!$B14) -> 0 | E14: =SUMIFS(Movements!$K:$K,Movements!$A:$A,E$2,Movements!$G:$G,$A14,Movements!$D:$D,'P&L'!$B14) -> -3005.8125 | F14: =SUMIFS(Movements!$K:$K,Movements!$A:$A,F$2,Movements!$G:$G,$A14,Movements!$D:$D,'P&L'!$B14) -> -4715 | G14: =SUMIFS(Movements!$K:$K,Movements!$A:$A,G$2,Movements!$G:$G,$A14,Movements!$D:$D,'P&L'!$B14) -> -3960.6 | H14: =SUM(D14:G14) -> -11681.413
B15: SFG | C15: consumption @ std | D15: =-'Formulation & overusage'!D107 -> 0 | E15: =-'Formulation & overusage'!E107 -> -3005.8125 | F15: =-'Formulation & overusage'!F107 -> -4715 | G15: =-'Formulation & overusage'!G107 -> -3921.96 | H15: ='Formulation & overusage'!H107 -> 0
B16: SFG | C16: Overusage variance | D16: =-'Formulation & overusage'!D104 -> 0 | E16: =-'Formulation & overusage'!E104 -> -29.325 | F16: =-'Formulation & overusage'!F104 -> -46 | G16: =-'Formulation & overusage'!G104 -> 0 | H16: =-'Formulation & overusage'!H104 -> 0
B17: SFG | C17: Formulation variance | D17: =-'Formulation & overusage'!D101 -> 0 | E17: =-'Formulation & overusage'!E101 -> 29.325 | F17: =-'Formulation & overusage'!F101 -> 46 | G17: =-'Formulation & overusage'!G101 -> -38.64 | H17: =-'Formulation & overusage'!H101 -> 0
A18: P | B18: SFG | C18: SFG output / production | D18: =SUMIFS(Movements!$K:$K,Movements!$A:$A,D$2,Movements!$G:$G,$A18,Movements!$D:$D,'P&L'!$B18) -> 0 | E18: =SUMIFS(Movements!$K:$K,Movements!$A:$A,E$2,Movements!$G:$G,$A18,Movements!$D:$D,'P&L'!$B18) -> 3162.5 | F18: =SUMIFS(Movements!$K:$K,Movements!$A:$A,F$2,Movements!$G:$G,$A18,Movements!$D:$D,'P&L'!$B18) -> 5895.1875 | G18: =SUMIFS(Movements!$K:$K,Movements!$A:$A,G$2,Movements!$G:$G,$A18,Movements!$D:$D,'P&L'!$B18) -> 2760 | H18: =SUM(D18:G18) -> 11817.688
A19: S | B19: SFG | C19: SFG write-off | D19: =SUMIFS(Movements!$K:$K,Movements!$A:$A,D$2,Movements!$G:$G,$A19,Movements!$D:$D,'P&L'!$B19) -> 0 | E19: =SUMIFS(Movements!$K:$K,Movements!$A:$A,E$2,Movements!$G:$G,$A19,Movements!$D:$D,'P&L'!$B19) -> 0 | F19: =SUMIFS(Movements!$K:$K,Movements!$A:$A,F$2,Movements!$G:$G,$A19,Movements!$D:$D,'P&L'!$B19) -> 0 | G19: =SUMIFS(Movements!$K:$K,Movements!$A:$A,G$2,Movements!$G:$G,$A19,Movements!$D:$D,'P&L'!$B19) -> 0 | H19: =SUM(D19:G19) -> 0
A20: I | B20: SFG | C20: SFG stock adjusments | D20: =SUMIFS(Movements!$K:$K,Movements!$A:$A,D$2,Movements!$G:$G,$A20,Movements!$D:$D,'P&L'!$B20) -> 0 | E20: =SUMIFS(Movements!$K:$K,Movements!$A:$A,E$2,Movements!$G:$G,$A20,Movements!$D:$D,'P&L'!$B20) -> 0 | F20: =SUMIFS(Movements!$K:$K,Movements!$A:$A,F$2,Movements!$G:$G,$A20,Movements!$D:$D,'P&L'!$B20) -> -86.25 | G20: =SUMIFS(Movements!$K:$K,Movements!$A:$A,G$2,Movements!$G:$G,$A20,Movements!$D:$D,'P&L'!$B20) -> 0 | H20: =SUM(D20:G20) -> -86.25
B21: SFG | C21: Stock reevaluation SFG | D21: ='Stock reval'!E34 -> 0 | E21: ='Stock reval'!F34 -> 0 | F21: ='Stock reval'!G34 -> -100.05 | G21: ='Stock reval'!H34 -> 50.025 | H21: =SUM(D21:G21) -> -50.025
A23: P | B23: FG | C23: FG output / production | D23: =SUMIFS(Movements!$K:$K,Movements!$A:$A,D$2,Movements!$G:$G,$A23,Movements!$D:$D,'P&L'!$B23) -> 0 | E23: =SUMIFS(Movements!$K:$K,Movements!$A:$A,E$2,Movements!$G:$G,$A23,Movements!$D:$D,'P&L'!$B23) -> 39841.353 | F23: =SUMIFS(Movements!$K:$K,Movements!$A:$A,F$2,Movements!$G:$G,$A23,Movements!$D:$D,'P&L'!$B23) -> 60715.7 | G23: =SUMIFS(Movements!$K:$K,Movements!$A:$A,G$2,Movements!$G:$G,$A23,Movements!$D:$D,'P&L'!$B23) -> 29102.21 | H23: =SUM(D23:G23) -> 129659.26
A24: D | B24: FG | C24: FG dispatch (sales) | D24: =SUMIFS(Movements!$K:$K,Movements!$A:$A,D$2,Movements!$G:$G,$A24,Movements!$D:$D,'P&L'!$B24) -> 0 | E24: =SUMIFS(Movements!$K:$K,Movements!$A:$A,E$2,Movements!$G:$G,$A24,Movements!$D:$D,'P&L'!$B24) -> -21146.825 | F24: =SUMIFS(Movements!$K:$K,Movements!$A:$A,F$2,Movements!$G:$G,$A24,Movements!$D:$D,'P&L'!$B24) -> -58251.475 | G24: =SUMIFS(Movements!$K:$K,Movements!$A:$A,G$2,Movements!$G:$G,$A24,Movements!$D:$D,'P&L'!$B24) -> -51857.84 | H24: =SUM(D24:G24) -> -131256.14
A25: W | B25: FG | C25: FG write-off | D25: =SUMIFS(Movements!$K:$K,Movements!$A:$A,D$2,Movements!$G:$G,$A25,Movements!$D:$D,'P&L'!$B25) -> 0 | E25: =SUMIFS(Movements!$K:$K,Movements!$A:$A,E$2,Movements!$G:$G,$A25,Movements!$D:$D,'P&L'!$B25) -> 0 | F25: =SUMIFS(Movements!$K:$K,Movements!$A:$A,F$2,Movements!$G:$G,$A25,Movements!$D:$D,'P&L'!$B25) -> 0 | G25: =SUMIFS(Movements!$K:$K,Movements!$A:$A,G$2,Movements!$G:$G,$A25,Movements!$D:$D,'P&L'!$B25) -> -85.35 | H25: =SUM(D25:G25) -> -85.35
A26: I | B26: FG | C26: FG stock adjusments | D26: =SUMIFS(Movements!$K:$K,Movements!$A:$A,D$2,Movements!$G:$G,$A26,Movements!$D:$D,'P&L'!$B26) -> 0 | E26: =SUMIFS(Movements!$K:$K,Movements!$A:$A,E$2,Movements!$G:$G,$A26,Movements!$D:$D,'P&L'!$B26) -> 0 | F26: =SUMIFS(Movements!$K:$K,Movements!$A:$A,F$2,Movements!$G:$G,$A26,Movements!$D:$D,'P&L'!$B26) -> -272.4775 | G26: =SUMIFS(Movements!$K:$K,Movements!$A:$A,G$2,Movements!$G:$G,$A26,Movements!$D:$D,'P&L'!$B26) -> 0 | H26: =SUM(D26:G26) -> -272.4775
B27: FG | C27: Stock reevaluation FG | D27: ='Stock reval'!E39 -> 0 | E27: ='Stock reval'!F39 -> 1491.04 | F27: ='Stock reval'!G39 -> 1145.71 | G27: ='Stock reval'!H39 -> -682.045 | H27: =SUM(D27:G27) -> 1954.705
C29: Slow moving provision | D29: ='Slow moving'!D36 -> 0 | E29: ='Slow moving'!E36 -> -3336.9438 | F29: ='Slow moving'!F36 -> 3336.9438 | G29: ='Slow moving'!G36 -> 0 | H29: =SUM(D29:G29) -> 0
C30: LOCOM provision | D30: =LOCOM!E14 -> 0 | E30: =LOCOM!F14 -> 0 | F30: =LOCOM!G14 -> -661.5 | G30: =LOCOM!H14 -> 661.5 | H30: =SUM(D30:G30) -> 0
I31: check
C32: TOTAL RM cost | D32: =SUM(D3:D30)-D6-D14 -> 0 | E32: =SUM(E3:E30)-E6-E14 -> -24304.001 | F32: =SUM(F3:F30)-F6-F14 -> -60265.799 | G32: =SUM(G3:G30)-G6-G14 -> -52447.7 | H32: =SUM(D32:G32) -> -137017.5 | I32: =H32+SUM('Purchases & PPV'!K17:N17) -> 0
C34: TOTAL SALES | E34: =Sales!C13 -> 35200 | F34: =Sales!D13 -> 89200 | G34: =Sales!E13 -> 77000 | H34: =SUM(D34:G34) -> 201400
C36: RM % sales | E36: =E32/E34 -> -0.69045458 | F36: =F32/F34 -> -0.67562555 | G36: =G32/G34 -> -0.68113896 | H36: =H32/H34 -> -0.68032522

Sheet IS

Sheet .

Sheet   

Sheet SL
B2: SL (storage location) | C2: SL description
B3: IN | C3: Inbound warehouse
B4: NP | C4: Nut plant
B5: Fint L | C5: Fint production line
B6: Step L | C6: Step production line
B7: PL | C7: Palletizer
B8: OUT | C8: Outbound warehouse

Sheet list of materials
E1: Std material cost
A2: Material number | B2: Material | C2: Mat type | D2: Mat type description | E2: 2022 | F2: 2023
A3: 120301 | B3: Fint | C3: FG | D3: Finished goods | E3: ='BOM & Std price'!M7 -> 27.24775 | F3: ='BOM & Std price'!P7 -> 29.2598
A4: 156212 | B4: Step | C4: FG | D4: Finished goods | E4: ='BOM & Std price'!M29 -> 25.945 | F4: ='BOM & Std price'!P29 -> 28.45
A5: 867156 | B5: Chocolate mass | C5: RM | D5: Raw material | E5: 28 | F5: 31
A6: 765190 | B6: Caramel | C6: RM | D6: Raw material | E6: 15 | F6: 16
A7: 657341 | B7: Raw Peanut | C7: RM | D7: Raw material | E7: 25 | F7: 24
A8: 876145 | B8: Fried Peanut | C8: SFG | D8: Semi-finished goods | E8: ='BOM & Std price'!M17 -> 28.75 | F8: ='BOM & Std price'!P17 -> 27.6
A9: 560196 | B9: Biscuit | C9: RM | D9: Raw material | E9: 25 | F9: 27

Sheet BOM & Std price
K1: Std cost breakdown | L1: 2022 | O1: 2023
C2: Product | D2: Fint | E2: ='list of materials'!A3 -> 120301 | L2: kg | M2: Std cost/kg | N2: LC | O2: kg | P2: Std cost/kg | Q2: LC
C3: Recipe per | D3: 1000 | E3: kg | K3: Chocolate mass | L3: =D7 -> 708 | M3: =VLOOKUP(K3,'list of materials'!B:E,4,0) -> 28 | N3: =M3*L3 -> 19824 | O3: =H7 -> 711 | P3: =VLOOKUP(K3,'list of materials'!B:F,5,0) -> 31 | Q3: =P3*O3 -> 22041
C4: Recipe type | D4: Std | K4: Fried Peanut | L4: =D8 -> 205 | M4: =VLOOKUP(K4,'list of materials'!B:E,4,0) -> 28.75 | N4: =M4*L4 -> 5893.75 | O4: =H8 -> 203 | P4: =VLOOKUP(K4,'list of materials'!B:F,5,0) -> 27.6 | Q4: =P4*O4 -> 5602.8
D5: kg / 1000 kg | K5: Caramel | L5: =D9 -> 102 | M5: =VLOOKUP(K5,'list of materials'!B:E,4,0) -> 15 | N5: =M5*L5 -> 1530 | O5: =H9 -> 101 | P5: =VLOOKUP(K5,'list of materials'!B:F,5,0) -> 16 | Q5: =P5*O5 -> 1616
A6: Mat type | B6: Alternative | C6: Mat number | D6: Std'22 | E6: Oct act | F6: Nov act | G6: Dec act | H6: Std'23 | I6: Jan act
A7: RM | B7: Chocolate mass | C7: ='list of materials'!A5 -> 867156 | D7: 708 | E7: 708 | F7: 711 | G7: 711 | H7: 711 | I7: 708 | K7: Material cost | M7: =N7/D3 -> 27.24775 | N7: =SUM(N3:N5) -> 27247.75 | P7: =Q7/D3 -> 29.2598 | Q7: =SUM(Q3:Q5) -> 29259.8
A8: SFG | B8: Fried Peanut | C8: ='list of materials'!A8 -> 876145 | D8: 205 | E8: 205 | F8: 203 | G8: 203 | H8: 203 | I8: 205 | K8: Variable conv cost | M8: Direct labor | N8: 2000 | P8: Direct labor | Q8: 2000
A9: RM | B9: Caramel | C9: ='list of materials'!A6 -> 765190 | D9: 102 | E9: 102 | F9: 101 | G9: 101 | H9: 101 | I9: 102 | K9: Variable conv cost | M9: Energy | N9: 1000 | P9: Energy | Q9: 1000
B10: Total | D10: =SUM(D7:D9) -> 1015 | E10: =SUM(E7:E9) -> 1015 | F10: =SUM(F7:F9) -> 1015 | G10: =SUM(G7:G9) -> 1015 | H10: =SUM(H7:H9) -> 1015 | I10: =SUM(I7:I9) -> 1015 | K10: Fixed MFG ОHs | M10: MFG Fixed | N10: 800 | P10: MFG Fixed | Q10: 800
B11: Designed process loss | D11: =D10/$D$3-1 -> 0.015 | E11: =E10/$D$3-1 -> 0.015 | F11: =F10/$D$3-1 -> 0.015 | G11: =G10/$D$3-1 -> 0.015 | H11: =H10/$D$3-1 -> 0.015 | I11: =I10/$D$3-1 -> 0.015 | K11: Standard cost | M11: =N11/D3 -> 31.04775 | N11: =SUM(N7:N10) -> 31047.75 | P11: =Q11/D3 -> 33.0598 | Q11: =SUM(Q7:Q10) -> 33059.8
C13: Product | D13: Fried Peanut | K13: Std cost breakdown | L13: 2022 | O13: 2023
C14: Recipe per | D14: 1000 | E14: kg | L14: kg | M14: Std cost/kg | N14: LC | O14: kg | P14: Std cost/kg | Q14: LC
C15: Recipe type | D15: Std | K15: Raw Peanut | L15: =D18 -> 1150 | M15: =VLOOKUP(K15,'list of materials'!B:E,4,0) -> 25 | N15: =M15*L15 -> 28750 | O15: =H18 -> 1150 | P15: =VLOOKUP(K15,'list of materials'!B:F,5,0) -> 24 | Q15: =P15*O15 -> 27600
D16: kg / 1000 kg
A17: Mat type | B17: Alternative | C17: Mat number | D17: Std'22 | E17: Oct act | F17: Nov act | G17: Dec act | H17: Std'23 | I17: Jan act | K17: Material cost | M17: =N17/D14 -> 28.75 | N17: =SUM(N13:N15) -> 28750 | P17: =Q17/D14 -> 27.6 | Q17: =SUM(Q13:Q15) -> 27600
A18: RM | B18: Raw Peanut | C18: ='list of materials'!A7 -> 657341 | D18: 1150 | E18: 1150 | F18: 1150 | G18: 1150 | H18: 1150 | I18: 1150 | K18: Variable conv cost | M18: Direct labor | N18: 500 | P18: Direct labor | Q18: 500
B19: Total | D19: =SUM(D18) -> 1150 | E19: =SUM(E18) -> 1150 | F19: =SUM(F18) -> 1150 | G19: =SUM(G18) -> 1150 | H19: =SUM(H18) -> 1150 | I19: =SUM(I18) -> 1150 | K19: Variable conv cost | M19: Energy | N19: 400 | P19: Energy | Q19: 400
B20: Designed process loss | D20: =D19/$D$14-1 -> 0.15 | E20: =E19/$D$14-1 -> 0.15 | F20: =F19/$D$14-1 -> 0.15 | G20: =G19/$D$14-1 -> 0.15 | H20: =H19/$D$14-1 -> 0.15 | I20: =I19/$D$14-1 -> 0.15 | K20: Fixed MFG ОHs | M20: MFG Fixed | N20: 200 | P20: MFG Fixed | Q20: 200
K21: Standard cost | M21: =N21/D14 -> 29.85 | N21: =SUM(N17:N20) -> 29850 | P21: =Q21/D14 -> 28.7 | Q21: =SUM(Q17:Q20) -> 28700
C23: Product | D23: Step | K23: Std cost breakdown | L23: 2022 | O23: 2023
C24: Recipe per | D24: 1000 | E24: kg | L24: kg | M24: Std cost/kg | N24: LC | O24: kg | P24: Std cost/kg | Q24: LC
C25: Recipe type | D25: Std | K25: Chocolate mass | L25: =D29 -> 590 | M25: =VLOOKUP(K25,'list of materials'!B:E,4,0) -> 28 | N25: =M25*L25 -> 16520 | O25: =H29 -> 590 | P25: =VLOOKUP(K25,'list of materials'!B:F,5,0) -> 31 | Q25: =P25*O25 -> 18290
K26: Biscuit | L26: =D30 -> 320 | M26: =VLOOKUP(K26,'list of materials'!B:E,4,0) -> 25 | N26: =M26*L26 -> 8000 | O26: =H30 -> 320 | P26: =VLOOKUP(K26,'list of materials'!B:F,5,0) -> 27 | Q26: =P26*O26 -> 8640
D27: kg / 1000 kg | K27: Caramel | L27: =D31 -> 95 | M27: =VLOOKUP(K27,'list of materials'!B:E,4,0) -> 15 | N27: =M27*L27 -> 1425 | O27: =H31 -> 95 | P27: =VLOOKUP(K27,'list of materials'!B:F,5,0) -> 16 | Q27: =P27*O27 -> 1520
A28: Mat type | B28: Alternative | C28: Mat number | D28: Std'22 | E28: Oct act | F28: Nov act | G28: Dec act | H28: Std'23 | I28: Jan act
A29: RM | B29: Chocolate mass | C29: ='list of materials'!A5 -> 867156 | D29: 590 | E29: 590 | F29: 590 | G29: 590 | H29: 590 | I29: 590 | K29: Material cost | M29: =N29/D24 -> 25.945 | N29: =SUM(N25:N27) -> 25945 | P29: =Q29/D24 -> 28.45 | Q29: =SUM(Q25:Q27) -> 28450
A30: RM | B30: Biscuit | C30: ='list of materials'!A9 -> 560196 | D30: 320 | E30: 320 | F30: 320 | G30: 320 | H30: 320 | I30: 320 | K30: Variable conv cost | M30: Direct labor | N30: 2200 | P30: Direct labor | Q30: 2200
A31: RM | B31: Caramel | C31: ='list of materials'!A6 -> 765190 | D31: 95 | E31: 95 | F31: 95 | G31: 95 | H31: 95 | I31: 95 | K31: Variable conv cost | M31: Energy | N31: 900 | P31: Energy | Q31: 900
B32: Total | D32: =SUM(D29:D31) -> 1005 | E32: =SUM(E29:E31) -> 1005 | F32: =SUM(F29:F31) -> 1005 | G32: =SUM(G29:G31) -> 1005 | H32: =SUM(H29:H31) -> 1005 | I32: =SUM(I29:I31) -> 1005 | K32: Fixed MFG ОHs | M32: MFG Fixed | N32: 800 | P32: MFG Fixed | Q32: 800
B33: Designed process loss | D33: =D32/$D$24-1 -> 0.005 | E33: =E32/$D$24-1 -> 0.005 | F33: =F32/$D$24-1 -> 0.005 | G33: =G32/$D$24-1 -> 0.005 | H33: =H32/$D$24-1 -> 0.005 | I33: =I32/$D$24-1 -> 0.005 | K33: Standard cost | M33: =N33/D24 -> 29.845 | N33: =SUM(N29:N32) -> 29845 | P33: =Q33/D24 -> 32.35 | Q33: =SUM(Q29:Q32) -> 32350

Sheet MvT types
B2: Movement | C2: Movement description
B3: R | C3: reception
B4: C | C4: consumption
B5: M | C5: internal movement
B6: P | C6: goods production
B7: W | C7: Write-off
B8: I | C8: Inventory stock-take
B9: D | C9: dispatch

Sheet Movements
A1: Month | B1: Material | C1: Mat descr | D1: Material type | E1: SL | F1: Storage location | G1: Movement | H1: Movement type | I1: Quantity | J1: Std price | K1: Amount local currency
A2: October | B2: 867156 | C2: =VLOOKUP(B2,'list of materials'!A:B,2,0) -> Chocolate mass | D2: =VLOOKUP(B2,'list of materials'!A:C,3,0) -> RM | E2: IN | F2: =VLOOKUP(E2,SL!B:C,2,0) -> Inbound warehouse | G2: R | H2: =VLOOKUP(G2,'MvT types'!B:C,2,0) -> reception | I2: 2481 | J2: =VLOOKUP(B2,'list of materials'!A:E,5,0) -> 28 | K2: =I2*J2 -> 69468
A3: October | B3: 765190 | C3: =VLOOKUP(B3,'list of materials'!A:B,2,0) -> Caramel | D3: =VLOOKUP(B3,'list of materials'!A:C,3,0) -> RM | E3: IN | F3: =VLOOKUP(E3,SL!B:C,2,0) -> Inbound warehouse | G3: R | H3: =VLOOKUP(G3,'MvT types'!B:C,2,0) -> reception | I3: 198 | J3: =VLOOKUP(B3,'list of materials'!A:E,5,0) -> 15 | K3: =I3*J3 -> 2970
A4: October | B4: 657341 | C4: =VLOOKUP(B4,'list of materials'!A:B,2,0) -> Raw Peanut | D4: =VLOOKUP(B4,'list of materials'!A:C,3,0) -> RM | E4: IN | F4: =VLOOKUP(E4,SL!B:C,2,0) -> Inbound warehouse | G4: R | H4: =VLOOKUP(G4,'MvT types'!B:C,2,0) -> reception | I4: 89.5 | J4: =VLOOKUP(B4,'list of materials'!A:E,5,0) -> 25 | K4: =I4*J4 -> 2237.5
A5: October | B5: 560196 | C5: =VLOOKUP(B5,'list of materials'!A:B,2,0) -> Biscuit | D5: =VLOOKUP(B5,'list of materials'!A:C,3,0) -> RM | E5: IN | F5: =VLOOKUP(E5,SL!B:C,2,0) -> Inbound warehouse | G5: R | H5: =VLOOKUP(G5,'MvT types'!B:C,2,0) -> reception | I5: 330 | J5: =VLOOKUP(B5,'list of materials'!A:E,5,0) -> 25 | K5: =I5*J5 -> 8250
A6: October | B6: 560196 | C6: =VLOOKUP(B6,'list of materials'!A:B,2,0) -> Biscuit | D6: =VLOOKUP(B6,'list of materials'!A:C,3,0) -> RM | E6: IN | F6: =VLOOKUP(E6,SL!B:C,2,0) -> Inbound warehouse | G6: R | H6: =VLOOKUP(G6,'MvT types'!B:C,2,0) -> reception | I6: -100 | J6: =VLOOKUP(B6,'list of materials'!A:E,5,0) -> 25 | K6: =I6*J6 -> -2500
A7: November | B7: 120301 | C7: =VLOOKUP(B7,'list of materials'!A:B,2,0) -> Fint | D7: =VLOOKUP(B7,'list of materials'!A:C,3,0) -> FG | E7: PL | F7: =VLOOKUP(E7,SL!B:C,2,0) -> Palletizer | G7: P | H7: =VLOOKUP(G7,'MvT types'!B:C,2,0) -> goods production | I7: 510 | J7: =VLOOKUP(B7,'list of materials'!A:E,5,0) -> 27.24775 | K7: =I7*J7 -> 13896.352
A8: November | B8: 156212 | C8: =VLOOKUP(B8,'list of materials'!A:B,2,0) -> Step | D8: =VLOOKUP(B8,'list of materials'!A:C,3,0) -> FG | E8: PL | F8: =VLOOKUP(E8,SL!B:C,2,0) -> Palletizer | G8: P | H8: =VLOOKUP(G8,'MvT types'!B:C,2,0) -> goods production | I8: 1000 | J8: =VLOOKUP(B8,'list of materials'!A:E,5,0) -> 25.945 | K8: =I8*J8 -> 25945
A9: November | B9: 876145 | C9: =VLOOKUP(B9,'list of materials'!A:B,2,0) -> Fried Peanut | D9: =VLOOKUP(B9,'list of materials'!A:C,3,0) -> SFG | E9: NP | F9: =VLOOKUP(E9,SL!B:C,2,0) -> Nut plant | G9: P | H9: =VLOOKUP(G9,'MvT types'!B:C,2,0) -> goods production | I9: 110 | J9: =VLOOKUP(B9,'list of materials'!A:E,5,0) -> 28.75 | K9: =I9*J9 -> 3162.5
A10: December | B10: 120301 | C10: =VLOOKUP(B10,'list of materials'!A:B,2,0) -> Fint | D10: =VLOOKUP(B10,'list of materials'!A:C,3,0) -> FG | E10: PL | F10: =VLOOKUP(E10,SL!B:C,2,0) -> Palletizer | G10: P | H10: =VLOOKUP(G10,'MvT types'!B:C,2,0) -> goods production | I10: 800 | J10: =VLOOKUP(B10,'list of materials'!A:E,5,0) -> 27.24775 | K10: =I10*J10 -> 21798.2
A11: December | B11: 156212 | C11: =VLOOKUP(B11,'list of materials'!A:B,2,0) -> Step | D11: =VLOOKUP(B11,'list of materials'!A:C,3,0) -> FG | E11: PL | F11: =VLOOKUP(E11,SL!B:C,2,0) -> Palletizer | G11: P | H11: =VLOOKUP(G11,'MvT types'!B:C,2,0) -> goods production | I11: 1500 | J11: =VLOOKUP(B11,'list of materials'!A:E,5,0) -> 25.945 | K11: =I11*J11 -> 38917.5
A12: December | B12: 876145 | C12: =VLOOKUP(B12,'list of materials'!A:B,2,0) -> Fried Peanut | D12: =VLOOKUP(B12,'list of materials'!A:C,3,0) -> SFG | E12: NP | F12: =VLOOKUP(E12,SL!B:C,2,0) -> Nut plant | G12: P | H12: =VLOOKUP(G12,'MvT types'!B:C,2,0) -> goods production | I12: 205.05 | J12: =VLOOKUP(B12,'list of materials'!A:E,5,0) -> 28.75 | K12: =I12*J12 -> 5895.1875
A13: January | B13: 120301 | C13: =VLOOKUP(B13,'list of materials'!A:B,2,0) -> Fint | D13: =VLOOKUP(B13,'list of materials'!A:C,3,0) -> FG | E13: PL | F13: =VLOOKUP(E13,SL!B:C,2,0) -> Palletizer | G13: P | H13: =VLOOKUP(G13,'MvT types'!B:C,2,0) -> goods production | I13: 700 | J13: =VLOOKUP(B13,'list of materials'!A:F,6,0) -> 29.2598 | K13: =I13*J13 -> 20481.86
A14: January | B14: 156212 | C14: =VLOOKUP(B14,'list of materials'!A:B,2,0) -> Step | D14: =VLOOKUP(B14,'list of materials'!A:C,3,0) -> FG | E14: PL | F14: =VLOOKUP(E14,SL!B:C,2,0) -> Palletizer | G14: P | H14: =VLOOKUP(G14,'MvT types'!B:C,2,0) -> goods production | I14: 303 | J14: =VLOOKUP(B14,'list of materials'!A:F,6,0) -> 28.45 | K14: =I14*J14 -> 8620.35
A15: January | B15: 876145 | C15: =VLOOKUP(B15,'list of materials'!A:B,2,0) -> Fried Peanut | D15: =VLOOKUP(B15,'list of materials'!A:C,3,0) -> SFG | E15: NP | F15: =VLOOKUP(E15,SL!B:C,2,0) -> Nut plant | G15: P | H15: =VLOOKUP(G15,'MvT types'!B:C,2,0) -> goods production | I15: 100 | J15: =VLOOKUP(B15,'list of materials'!A:F,6,0) -> 27.6 | K15: =I15*J15 -> 2760
A16: November | B16: 120301 | C16: =VLOOKUP(B16,'list of materials'!A:B,2,0) -> Fint | D16: =VLOOKUP(B16,'list of materials'!A:C,3,0) -> FG | E16: PL | F16: =VLOOKUP(E16,SL!B:C,2,0) -> Palletizer | G16: M | H16: =VLOOKUP(G16,'MvT types'!B:C,2,0) -> internal movement | I16: -510 | J16: =VLOOKUP(B16,'list of materials'!A:E,5,0) -> 27.24775 | K16: =I16*J16 -> -13896.352
A17: November | B17: 156212 | C17: =VLOOKUP(B17,'list of materials'!A:B,2,0) -> Step | D17: =VLOOKUP(B17,'list of materials'!A:C,3,0) -> FG | E17: PL | F17: =VLOOKUP(E17,SL!B:C,2,0) -> Palletizer | G17: M | H17: =VLOOKUP(G17,'MvT types'!B:C,2,0) -> internal movement | I17: -1000 | J17: =VLOOKUP(B17,'list of materials'!A:E,5,0) -> 25.945 | K17: =I17*J17 -> -25945
A18: December | B18: 120301 | C18: =VLOOKUP(B18,'list of materials'!A:B,2,0) -> Fint | D18: =VLOOKUP(B18,'list of materials'!A:C,3,0) -> FG | E18: PL | F18: =VLOOKUP(E18,SL!B:C,2,0) -> Palletizer | G18: M | H18: =VLOOKUP(G18,'MvT types'!B:C,2,0) -> internal movement | I18: -800 | J18: =VLOOKUP(B18,'list of materials'!A:E,5,0) -> 27.24775 | K18: =I18*J18 -> -21798.2
A19: December | B19: 156212 | C19: =VLOOKUP(B19,'list of materials'!A:B,2,0) -> Step | D19: =VLOOKUP(B19,'list of materials'!A:C,3,0) -> FG | E19: PL | F19: =VLOOKUP(E19,SL!B:C,2,0) -> Palletizer | G19: M | H19: =VLOOKUP(G19,'MvT types'!B:C,2,0) -> internal movement | I19: -1500 | J19: =VLOOKUP(B19,'list of materials'!A:E,5,0) -> 25.945 | K19: =I19*J19 -> -38917.5
A20: January | B20: 120301 | C20: =VLOOKUP(B20,'list of materials'!A:B,2,0) -> Fint | D20: =VLOOKUP(B20,'list of materials'!A:C,3,0) -> FG | E20: PL | F20: =VLOOKUP(E20,SL!B:C,2,0) -> Palletizer | G20: M | H20: =VLOOKUP(G20,'MvT types'!B:C,2,0) -> internal movement | I20: -700 | J20: =VLOOKUP(B20,'list of materials'!A:F,6,0) -> 29.2598 | K20: =I20*J20 -> -20481.86
A21: January | B21: 156212 | C21: =VLOOKUP(B21,'list of materials'!A:B,2,0) -> Step | D21: =VLOOKUP(B21,'list of materials'!A:C,3,0) -> FG | E21: PL | F21: =VLOOKUP(E21,SL!B:C,2,0) -> Palletizer | G21: M | H21: =VLOOKUP(G21,'MvT types'!B:C,2,0) -> internal movement | I21: -303 | J21: =VLOOKUP(B21,'list of materials'!A:F,6,0) -> 28.45 | K21: =I21*J21 -> -8620.35
A22: November | B22: 120301 | C22: =VLOOKUP(B22,'list of materials'!A:B,2,0) -> Fint | D22: =VLOOKUP(B22,'list of materials'!A:C,3,0) -> FG | E22: OUT | F22: =VLOOKUP(E22,SL!B:C,2,0) -> Outbound warehouse | G22: M | H22: =VLOOKUP(G22,'MvT types'!B:C,2,0) -> internal movement | I22: 510 | J22: =VLOOKUP(B22,'list of materials'!A:E,5,0) -> 27.24775 | K22: =I22*J22 -> 13896.352
A23: November | B23: 156212 | C23: =VLOOKUP(B23,'list of materials'!A:B,2,0) -> Step | D23: =VLOOKUP(B23,'list of materials'!A:C,3,0) -> FG | E23: OUT | F23: =VLOOKUP(E23,SL!B:C,2,0) -> Outbound warehouse | G23: M | H23: =VLOOKUP(G23,'MvT types'!B:C,2,0) -> internal movement | I23: 1000 | J23: =VLOOKUP(B23,'list of materials'!A:E,5,0) -> 25.945 | K23: =I23*J23 -> 25945
A24: December | B24: 120301 | C24: =VLOOKUP(B24,'list of materials'!A:B,2,0) -> Fint | D24: =VLOOKUP(B24,'list of materials'!A:C,3,0) -> FG | E24: OUT | F24: =VLOOKUP(E24,SL!B:C,2,0) -> Outbound warehouse | G24: M | H24: =VLOOKUP(G24,'MvT types'!B:C,2,0) -> internal movement | I24: 800 | J24: =VLOOKUP(B24,'list of materials'!A:E,5,0) -> 27.24775 | K24: =I24*J24 -> 21798.2
A25: December | B25: 156212 | C25: =VLOOKUP(B25,'list of materials'!A:B,2,0) -> Step | D25: =VLOOKUP(B25,'list of materials'!A:C,3,0) -> FG | E25: OUT | F25: =VLOOKUP(E25,SL!B:C,2,0) -> Outbound warehouse | G25: M | H25: =VLOOKUP(G25,'MvT types'!B:C,2,0) -> internal movement | I25: 1500 | J25: =VLOOKUP(B25,'list of materials'!A:E,5,0) -> 25.945 | K25: =I25*J25 -> 38917.5
A26: January | B26: 120301 | C26: =VLOOKUP(B26,'list of materials'!A:B,2,0) -> Fint | D26: =VLOOKUP(B26,'list of materials'!A:C,3,0) -> FG | E26: OUT | F26: =VLOOKUP(E26,SL!B:C,2,0) -> Outbound warehouse | G26: M | H26: =VLOOKUP(G26,'MvT types'!B:C,2,0) -> internal movement | I26: 700 | J26: =VLOOKUP(B26,'list of materials'!A:F,6,0) -> 29.2598 | K26: =I26*J26 -> 20481.86
A27: January | B27: 156212 | C27: =VLOOKUP(B27,'list of materials'!A:B,2,0) -> Step | D27: =VLOOKUP(B27,'list of materials'!A:C,3,0) -> FG | E27: OUT | F27: =VLOOKUP(E27,SL!B:C,2,0) -> Outbound warehouse | G27: M | H27: =VLOOKUP(G27,'MvT types'!B:C,2,0) -> internal movement | I27: 303 | J27: =VLOOKUP(B27,'list of materials'!A:F,6,0) -> 28.45 | K27: =I27*J27 -> 8620.35
A28: November | B28: 120301 | C28: =VLOOKUP(B28,'list of materials'!A:B,2,0) -> Fint | D28: =VLOOKUP(B28,'list of materials'!A:C,3,0) -> FG | E28: OUT | F28: =VLOOKUP(E28,SL!B:C,2,0) -> Outbound warehouse | G28: D | H28: =VLOOKUP(G28,'MvT types'!B:C,2,0) -> dispatch | I28: -300 | J28: =VLOOKUP(B28,'list of materials'!A:E,5,0) -> 27.24775 | K28: =I28*J28 -> -8174.325
A29: November | B29: 156212 | C29: =VLOOKUP(B29,'list of materials'!A:B,2,0) -> Step | D29: =VLOOKUP(B29,'list of materials'!A:C,3,0) -> FG | E29: OUT | F29: =VLOOKUP(E29,SL!B:C,2,0) -> Outbound warehouse | G29: D | H29: =VLOOKUP(G29,'MvT types'!B:C,2,0) -> dispatch | I29: -500 | J29: =VLOOKUP(B29,'list of materials'!A:E,5,0) -> 25.945 | K29: =I29*J29 -> -12972.5
A30: December | B30: 120301 | C30: =VLOOKUP(B30,'list of materials'!A:B,2,0) -> Fint | D30: =VLOOKUP(B30,'list of materials'!A:C,3,0) -> FG | E30: OUT | F30: =VLOOKUP(E30,SL!B:C,2,0) -> Outbound warehouse | G30: D | H30: =VLOOKUP(G30,'MvT types'!B:C,2,0) -> dispatch | I30: -900 | J30: =VLOOKUP(B30,'list of materials'!A:E,5,0) -> 27.24775 | K30: =I30*J30 -> -24522.975
A31: December | B31: 156212 | C31: =VLOOKUP(B31,'list of materials'!A:B,2,0) -> Step | D31: =VLOOKUP(B31,'list of materials'!A:C,3,0) -> FG | E31: OUT | F31: =VLOOKUP(E31,SL!B:C,2,0) -> Outbound warehouse | G31: D | H31: =VLOOKUP(G31,'MvT types'!B:C,2,0) -> dispatch | I31: -1300 | J31: =VLOOKUP(B31,'list of materials'!A:E,5,0) -> 25.945 | K31: =I31*J31 -> -33728.5
A32: January | B32: 120301 | C32: =VLOOKUP(B32,'list of materials'!A:B,2,0) -> Fint | D32: =VLOOKUP(B32,'list of materials'!A:C,3,0) -> FG | E32: OUT | F32: =VLOOKUP(E32,SL!B:C,2,0) -> Outbound warehouse | G32: D | H32: =VLOOKUP(G32,'MvT types'!B:C,2,0) -> dispatch | I32: -800 | J32: =VLOOKUP(B32,'list of materials'!A:F,6,0) -> 29.2598 | K32: =I32*J32 -> -23407.84
A33: January | B33: 156212 | C33: =VLOOKUP(B33,'list of materials'!A:B,2,0) -> Step | D33: =VLOOKUP(B33,'list of materials'!A:C,3,0) -> FG | E33: OUT | F33: =VLOOKUP(E33,SL!B:C,2,0) -> Outbound warehouse | G33: D | H33: =VLOOKUP(G33,'MvT types'!B:C,2,0) -> dispatch | I33: -1000 | J33: =VLOOKUP(B33,'list of materials'!A:F,6,0) -> 28.45 | K33: =I33*J33 -> -28450
A34: November | B34: 876145 | C34: =VLOOKUP(B34,'list of materials'!A:B,2,0) -> Fried Peanut | D34: =VLOOKUP(B34,'list of materials'!A:C,3,0) -> SFG | E34: NP | F34: =VLOOKUP(E34,SL!B:C,2,0) -> Nut plant | G34: M | H34: =VLOOKUP(G34,'MvT types'!B:C,2,0) -> internal movement | I34: -110 | J34: =VLOOKUP(B34,'list of materials'!A:E,5,0) -> 28.75 | K34: =I34*J34 -> -3162.5
A35: December | B35: 876145 | C35: =VLOOKUP(B35,'list of materials'!A:B,2,0) -> Fried Peanut | D35: =VLOOKUP(B35,'list of materials'!A:C,3,0) -> SFG | E35: NP | F35: =VLOOKUP(E35,SL!B:C,2,0) -> Nut plant | G35: M | H35: =VLOOKUP(G35,'MvT types'!B:C,2,0) -> internal movement | I35: -205.05 | J35: =VLOOKUP(B35,'list of materials'!A:E,5,0) -> 28.75 | K35: =I35*J35 -> -5895.1875
A36: January | B36: 876145 | C36: =VLOOKUP(B36,'list of materials'!A:B,2,0) -> Fried Peanut | D36: =VLOOKUP(B36,'list of materials'!A:C,3,0) -> SFG | E36: NP | F36: =VLOOKUP(E36,SL!B:C,2,0) -> Nut plant | G36: M | H36: =VLOOKUP(G36,'MvT types'!B:C,2,0) -> internal movement | I36: -100 | J36: =VLOOKUP(B36,'list of materials'!A:F,6,0) -> 27.6 | K36: =I36*J36 -> -2760
A37: November | B37: 876145 | C37: =VLOOKUP(B37,'list of materials'!A:B,2,0) -> Fried Peanut | D37: =VLOOKUP(B37,'list of materials'!A:C,3,0) -> SFG | E37: Fint L | F37: =VLOOKUP(E37,SL!B:C,2,0) -> Fint production line | G37: M | H37: =VLOOKUP(G37,'MvT types'!B:C,2,0) -> internal movement | I37: 110 | J37: =VLOOKUP(B37,'list of materials'!A:E,5,0) -> 28.75 | K37: =I37*J37 -> 3162.5
A38: December | B38: 876145 | C38: =VLOOKUP(B38,'list of materials'!A:B,2,0) -> Fried Peanut | D38: =VLOOKUP(B38,'list of materials'!A:C,3,0) -> SFG | E38: Fint L | F38: =VLOOKUP(E38,SL!B:C,2,0) -> Fint production line | G38: M | H38: =VLOOKUP(G38,'MvT types'!B:C,2,0) -> internal movement | I38: 205.05 | J38: =VLOOKUP(B38,'list of materials'!A:E,5,0) -> 28.75 | K38: =I38*J38 -> 5895.1875
A39: January | B39: 876145 | C39: =VLOOKUP(B39,'list of materials'!A:B,2,0) -> Fried Peanut | D39: =VLOOKUP(B39,'list of materials'!A:C,3,0) -> SFG | E39: Fint L | F39: =VLOOKUP(E39,SL!B:C,2,0) -> Fint production line | G39: M | H39: =VLOOKUP(G39,'MvT types'!B:C,2,0) -> internal movement | I39: 100 | J39: =VLOOKUP(B39,'list of materials'!A:F,6,0) -> 27.6 | K39: =I39*J39 -> 2760
A40: November | B40: 867156 | C40: =VLOOKUP(B40,'list of materials'!A:B,2,0) -> Chocolate mass | D40: =VLOOKUP(B40,'list of materials'!A:C,3,0) -> RM | E40: Fint L | F40: =VLOOKUP(E40,SL!B:C,2,0) -> Fint production line | G40: C | H40: =VLOOKUP(G40,'MvT types'!B:C,2,0) -> consumption | I40: -361.08 | J40: =VLOOKUP(B40,'list of materials'!A:E,5,0) -> 28 | K40: =I40*J40 -> -10110.24
...

Sheet MvT pivot
A1: Sum of Amount local currency | D1: Month
A2: Storage location | B2: Movement type | C2: Mat descr | D2: October | E2: November | F2: December | G2: January
A3: Fint production line | B3: consumption | C3: Caramel | E3: -780.3 | F3: -1224 | G3: -1142.4
C4: Chocolate mass | E4: -10110.24 | F4: -15859.2 | G4: -15363.6
C5: Fried Peanut | E5: -3005.8125 | F5: -4715 | G5: -3960.6
B6: consumption Total | E6: -13896.352 | F6: -21798.2 | G6: -20466.6
B7: internal movement | C7: Caramel | E7: 780.3 | F7: 1224 | G7: 1142.4
C8: Chocolate mass | E8: 10110.24 | F8: 15859.2 | G8: 15363.6
C9: Fried Peanut | E9: 6168.3125 | F9: 10610.188 | G9: 6720.6
B10: internal movement Total | E10: 17058.853 | F10: 27693.388 | G10: 23226.6
B11: Write-off | C11: Caramel | E11: -59.7 | F11: -15 | G11: -32
C12: Chocolate mass | E12: 114.24 | F12: -56 | G12: -124
B13: Write-off Total | E13: 54.54 | F13: -71 | G13: -156
A14: Fint production line Total | E14: 3217.04 | F14: 5824.1875 | G14: 2604
A15: Inbound warehouse | B15: internal movement | C15: Caramel | E15: -780.3 | F15: -1224 | G15: -1142.4
C16: Chocolate mass | E16: -10110.24 | F16: -15859.2 | G16: -15363.6
C17: Fried Peanut | E17: -3005.8125 | F17: -4715 | G17: -3960.6
C18: Raw Peanut | E18: -3017.3125 | F18: -5895.1875 | G18: -2760
B19: internal movement Total | E19: -16913.665 | F19: -27693.388 | G19: -23226.6
B20: Inventory stock-take | C20: Caramel | F20: -300
C21: Fint | F21: -272.4775
C22: Fried Peanut | F22: -86.25
C23: Raw Peanut | F23: -300
B24: Inventory stock-take Total | F24: -958.7275
B25: reception | C25: Biscuit | D25: 5750 | E25: 12500 | F25: 2500 | G25: 2403
C26: Caramel | D26: 2970 | E26: 3000 | F26: 750 | G26: 800
C27: Chocolate mass | D27: 69468 | E27: 11200 | F27: 2800 | G27: 3100
C28: Raw Peanut | D28: 2237.5 | E28: 7500 | F28: 1250 | G28: 1200
B29: reception Total | D29: 80425.5 | E29: 34200 | F29: 7300 | G29: 7503
A30: Inbound warehouse Total | D30: 80425.5 | E30: 17286.335 | F30: -21352.115 | G30: -15723.6
A31: Nut plant | B31: consumption | C31: Raw Peanut | E31: -3017.3125 | F31: -5895.1875 | G31: -2760
B32: consumption Total | E32: -3017.3125 | F32: -5895.1875 | G32: -2760
B33: goods production | C33: Fried Peanut | E33: 3162.5 | F33: 5895.1875 | G33: 2760
B34: goods production Total | E34: 3162.5 | F34: 5895.1875 | G34: 2760
B35: internal movement | C35: Fried Peanut | E35: -3162.5 | F35: -5895.1875 | G35: -2760
C36: Raw Peanut | E36: 3017.3125 | F36: 5895.1875 | G36: 2760
B37: internal movement Total | E37: -145.1875 | F37: 0 | G37: 0
B38: Write-off | C38: Raw Peanut | E38: -50 | F38: -75 | G38: -24
B39: Write-off Total | E39: -50 | F39: -75 | G39: -24
A40: Nut plant Total | E40: -50 | F40: -75 | G40: -24
...

Sheet Stocks
C1: Mat number | D1: Material | E1: October | F1: November | G1: December | H1: January
B2: Opening stock | C2: 120301 | D2: Fint | E2: 0 | F2: =E23 -> 0 | G2: =F23 -> 210 | H2: =G23 -> 100 | J2: R | K2: =VLOOKUP(J2,'MvT types'!B:C,2,0) -> reception
C3: 156212 | D3: Step | E3: 0 | F3: =E24 -> 0 | G3: =F24 -> 500 | H3: =G24 -> 700 | J3: C | K3: =VLOOKUP(J3,'MvT types'!B:C,2,0) -> consumption
C4: 867156 | D4: Chocolate mass | E4: 0 | F4: =E25 -> 2481 | G4: =F25 -> 1933 | H4: =G25 -> 578.6 | J4: M | K4: =VLOOKUP(J4,'MvT types'!B:C,2,0) -> internal movement
C5: 765190 | D5: Caramel | E5: 0 | F5: =E26 -> 198 | G5: =F26 -> 247 | H5: =G26 -> 51.9 | J5: P | K5: =VLOOKUP(J5,'MvT types'!B:C,2,0) -> goods production
C6: 657341 | D6: Raw Peanut | E6: 0 | F6: =E27 -> 89.5 | G6: =F27 -> 266.8075 | H6: =G27 -> 66 | J6: W | K6: =VLOOKUP(J6,'MvT types'!B:C,2,0) -> Write-off
C7: 876145 | D7: Fried Peanut | E7: 0 | F7: =E28 -> 0 | G7: =F28 -> 5.45 | H7: =G28 -> 43.5 | J7: I | K7: =VLOOKUP(J7,'MvT types'!B:C,2,0) -> Inventory stock-take
C8: 560196 | D8: Biscuit | E8: 0 | F8: =E29 -> 230 | G8: =F29 -> 390 | H8: =G29 -> 9 | J8: D | K8: =VLOOKUP(J8,'MvT types'!B:C,2,0) -> dispatch
B9: Inflow | C9: 120301 | D9: Fint | E9: =SUMIFS(Movements!$I:$I,Movements!$G:$G,$J$2,Movements!$B:$B,$C9,Movements!$A:$A,Stocks!E$1)+SUMIFS(Movements!$I:$I,Movements!$G:$G,$J$5,Movements!$B:$B,$C9,Movements!$A:$A,Stocks!E$1) -> 0 | F9: =SUMIFS(Movements!$I:$I,Movements!$G:$G,$J$2,Movements!$B:$B,$C9,Movements!$A:$A,Stocks!F$1)+SUMIFS(Movements!$I:$I,Movements!$G:$G,$J$5,Movements!$B:$B,$C9,Movements!$A:$A,Stocks!F$1) -> 510 | G9: =SUMIFS(Movements!$I:$I,Movements!$G:$G,$J$2,Movements!$B:$B,$C9,Movements!$A:$A,Stocks!G$1)+SUMIFS(Movements!$I:$I,Movements!$G:$G,$J$5,Movements!$B:$B,$C9,Movements!$A:$A,Stocks!G$1) -> 800 | H9: =SUMIFS(Movements!$I:$I,Movements!$G:$G,$J$2,Movements!$B:$B,$C9,Movements!$A:$A,Stocks!H$1)+SUMIFS(Movements!$I:$I,Movements!$G:$G,$J$5,Movements!$B:$B,$C9,Movements!$A:$A,Stocks!H$1) -> 700
C10: 156212 | D10: Step | E10: =SUMIFS(Movements!$I:$I,Movements!$G:$G,$J$2,Movements!$B:$B,$C10,Movements!$A:$A,Stocks!E$1)+SUMIFS(Movements!$I:$I,Movements!$G:$G,$J$5,Movements!$B:$B,$C10,Movements!$A:$A,Stocks!E$1) -> 0 | F10: =SUMIFS(Movements!$I:$I,Movements!$G:$G,$J$2,Movements!$B:$B,$C10,Movements!$A:$A,Stocks!F$1)+SUMIFS(Movements!$I:$I,Movements!$G:$G,$J$5,Movements!$B:$B,$C10,Movements!$A:$A,Stocks!F$1) -> 1000 | G10: =SUMIFS(Movements!$I:$I,Movements!$G:$G,$J$2,Movements!$B:$B,$C10,Movements!$A:$A,Stocks!G$1)+SUMIFS(Movements!$I:$I,Movements!$G:$G,$J$5,Movements!$B:$B,$C10,Movements!$A:$A,Stocks!G$1) -> 1500 | H10: =SUMIFS(Movements!$I:$I,Movements!$G:$G,$J$2,Movements!$B:$B,$C10,Movements!$A:$A,Stocks!H$1)+SUMIFS(Movements!$I:$I,Movements!$G:$G,$J$5,Movements!$B:$B,$C10,Movements!$A:$A,Stocks!H$1) -> 303
C11: 867156 | D11: Chocolate mass | E11: =SUMIFS(Movements!$I:$I,Movements!$G:$G,$J$2,Movements!$B:$B,$C11,Movements!$A:$A,Stocks!E$1)+SUMIFS(Movements!$I:$I,Movements!$G:$G,$J$5,Movements!$B:$B,$C11,Movements!$A:$A,Stocks!E$1) -> 2481 | F11: =SUMIFS(Movements!$I:$I,Movements!$G:$G,$J$2,Movements!$B:$B,$C11,Movements!$A:$A,Stocks!F$1)+SUMIFS(Movements!$I:$I,Movements!$G:$G,$J$5,Movements!$B:$B,$C11,Movements!$A:$A,Stocks!F$1) -> 400 | G11: =SUMIFS(Movements!$I:$I,Movements!$G:$G,$J$2,Movements!$B:$B,$C11,Movements!$A:$A,Stocks!G$1)+SUMIFS(Movements!$I:$I,Movements!$G:$G,$J$5,Movements!$B:$B,$C11,Movements!$A:$A,Stocks!G$1) -> 100 | H11: =SUMIFS(Movements!$I:$I,Movements!$G:$G,$J$2,Movements!$B:$B,$C11,Movements!$A:$A,Stocks!H$1)+SUMIFS(Movements!$I:$I,Movements!$G:$G,$J$5,Movements!$B:$B,$C11,Movements!$A:$A,Stocks!H$1) -> 100
C12: 765190 | D12: Caramel | E12: =SUMIFS(Movements!$I:$I,Movements!$G:$G,$J$2,Movements!$B:$B,$C12,Movements!$A:$A,Stocks!E$1)+SUMIFS(Movements!$I:$I,Movements!$G:$G,$J$5,Movements!$B:$B,$C12,Movements!$A:$A,Stocks!E$1) -> 198 | F12: =SUMIFS(Movements!$I:$I,Movements!$G:$G,$J$2,Movements!$B:$B,$C12,Movements!$A:$A,Stocks!F$1)+SUMIFS(Movements!$I:$I,Movements!$G:$G,$J$5,Movements!$B:$B,$C12,Movements!$A:$A,Stocks!F$1) -> 200 | G12: =SUMIFS(Movements!$I:$I,Movements!$G:$G,$J$2,Movements!$B:$B,$C12,Movements!$A:$A,Stocks!G$1)+SUMIFS(Movements!$I:$I,Movements!$G:$G,$J$5,Movements!$B:$B,$C12,Movements!$A:$A,Stocks!G$1) -> 50 | H12: =SUMIFS(Movements!$I:$I,Movements!$G:$G,$J$2,Movements!$B:$B,$C12,Movements!$A:$A,Stocks!H$1)+SUMIFS(Movements!$I:$I,Movements!$G:$G,$J$5,Movements!$B:$B,$C12,Movements!$A:$A,Stocks!H$1) -> 50
C13: 657341 | D13: Raw Peanut | E13: =SUMIFS(Movements!$I:$I,Movements!$G:$G,$J$2,Movements!$B:$B,$C13,Movements!$A:$A,Stocks!E$1)+SUMIFS(Movements!$I:$I,Movements!$G:$G,$J$5,Movements!$B:$B,$C13,Movements!$A:$A,Stocks!E$1) -> 89.5 | F13: =SUMIFS(Movements!$I:$I,Movements!$G:$G,$J$2,Movements!$B:$B,$C13,Movements!$A:$A,Stocks!F$1)+SUMIFS(Movements!$I:$I,Movements!$G:$G,$J$5,Movements!$B:$B,$C13,Movements!$A:$A,Stocks!F$1) -> 300 | G13: =SUMIFS(Movements!$I:$I,Movements!$G:$G,$J$2,Movements!$B:$B,$C13,Movements!$A:$A,Stocks!G$1)+SUMIFS(Movements!$I:$I,Movements!$G:$G,$J$5,Movements!$B:$B,$C13,Movements!$A:$A,Stocks!G$1) -> 50 | H13: =SUMIFS(Movements!$I:$I,Movements!$G:$G,$J$2,Movements!$B:$B,$C13,Movements!$A:$A,Stocks!H$1)+SUMIFS(Movements!$I:$I,Movements!$G:$G,$J$5,Movements!$B:$B,$C13,Movements!$A:$A,Stocks!H$1) -> 50
C14: 876145 | D14: Fried Peanut | E14: =SUMIFS(Movements!$I:$I,Movements!$G:$G,$J$2,Movements!$B:$B,$C14,Movements!$A:$A,Stocks!E$1)+SUMIFS(Movements!$I:$I,Movements!$G:$G,$J$5,Movements!$B:$B,$C14,Movements!$A:$A,Stocks!E$1) -> 0 | F14: =SUMIFS(Movements!$I:$I,Movements!$G:$G,$J$2,Movements!$B:$B,$C14,Movements!$A:$A,Stocks!F$1)+SUMIFS(Movements!$I:$I,Movements!$G:$G,$J$5,Movements!$B:$B,$C14,Movements!$A:$A,Stocks!F$1) -> 110 | G14: =SUMIFS(Movements!$I:$I,Movements!$G:$G,$J$2,Movements!$B:$B,$C14,Movements!$A:$A,Stocks!G$1)+SUMIFS(Movements!$I:$I,Movements!$G:$G,$J$5,Movements!$B:$B,$C14,Movements!$A:$A,Stocks!G$1) -> 205.05 | H14: =SUMIFS(Movements!$I:$I,Movements!$G:$G,$J$2,Movements!$B:$B,$C14,Movements!$A:$A,Stocks!H$1)+SUMIFS(Movements!$I:$I,Movements!$G:$G,$J$5,Movements!$B:$B,$C14,Movements!$A:$A,Stocks!H$1) -> 100
C15: 560196 | D15: Biscuit | E15: =SUMIFS(Movements!$I:$I,Movements!$G:$G,$J$2,Movements!$B:$B,$C15,Movements!$A:$A,Stocks!E$1)+SUMIFS(Movements!$I:$I,Movements!$G:$G,$J$5,Movements!$B:$B,$C15,Movements!$A:$A,Stocks!E$1) -> 230 | F15: =SUMIFS(Movements!$I:$I,Movements!$G:$G,$J$2,Movements!$B:$B,$C15,Movements!$A:$A,Stocks!F$1)+SUMIFS(Movements!$I:$I,Movements!$G:$G,$J$5,Movements!$B:$B,$C15,Movements!$A:$A,Stocks!F$1) -> 500 | G15: =SUMIFS(Movements!$I:$I,Movements!$G:$G,$J$2,Movements!$B:$B,$C15,Movements!$A:$A,Stocks!G$1)+SUMIFS(Movements!$I:$I,Movements!$G:$G,$J$5,Movements!$B:$B,$C15,Movements!$A:$A,Stocks!G$1) -> 100 | H15: =SUMIFS(Movements!$I:$I,Movements!$G:$G,$J$2,Movements!$B:$B,$C15,Movements!$A:$A,Stocks!H$1)+SUMIFS(Movements!$I:$I,Movements!$G:$G,$J$5,Movements!$B:$B,$C15,Movements!$A:$A,Stocks!H$1) -> 89
B16: Outflow | C16: 120301 | D16: Fint | E16: =SUMIFS(Movements!$I:$I,Movements!$G:$G,$J$3,Movements!$B:$B,$C16,Movements!$A:$A,Stocks!E$1)+SUMIFS(Movements!$I:$I,Movements!$G:$G,$J$6,Movements!$B:$B,$C16,Movements!$A:$A,Stocks!E$1)+SUMIFS(Movements!$I:$I,Movements!$G:$G,$J$7,Movements!$B:$B,$C16,Movements!$A:$A,Stocks!E$1)+SUMIFS(Movements!$I:$I,Movements!$G:$G,$J$8,Movements!$B:$B,$C16,Movements!$A:$A,Stocks!E$1) -> 0 | F16: =SUMIFS(Movements!$I:$I,Movements!$G:$G,$J$3,Movements!$B:$B,$C16,Movements!$A:$A,Stocks!F$1)+SUMIFS(Movements!$I:$I,Movements!$G:$G,$J$6,Movements!$B:$B,$C16,Movements!$A:$A,Stocks!F$1)+SUMIFS(Movements!$I:$I,Movements!$G:$G,$J$7,Movements!$B:$B,$C16,Movements!$A:$A,Stocks!F$1)+SUMIFS(Movements!$I:$I,Movements!$G:$G,$J$8,Movements!$B:$B,$C16,Movements!$A:$A,Stocks!F$1) -> -300 | G16: =SUMIFS(Movements!$I:$I,Movements!$G:$G,$J$3,Movements!$B:$B,$C16,Movements!$A:$A,Stocks!G$1)+SUMIFS(Movements!$I:$I,Movements!$G:$G,$J$6,Movements!$B:$B,$C16,Movements!$A:$A,Stocks!G$1)+SUMIFS(Movements!$I:$I,Movements!$G:$G,$J$7,Movements!$B:$B,$C16,Movements!$A:$A,Stocks!G$1)+SUMIFS(Movements!$I:$I,Movements!$G:$G,$J$8,Movements!$B:$B,$C16,Movements!$A:$A,Stocks!G$1) -> -910 | H16: =SUMIFS(Movements!$I:$I,Movements!$G:$G,$J$3,Movements!$B:$B,$C16,Movements!$A:$A,Stocks!H$1)+SUMIFS(Movements!$I:$I,Movements!$G:$G,$J$6,Movements!$B:$B,$C16,Movements!$A:$A,Stocks!H$1)+SUMIFS(Movements!$I:$I,Movements!$G:$G,$J$7,Movements!$B:$B,$C16,Movements!$A:$A,Stocks!H$1)+SUMIFS(Movements!$I:$I,Movements!$G:$G,$J$8,Movements!$B:$B,$C16,Movements!$A:$A,Stocks!H$1) -> -800
C17: 156212 | D17: Step | E17: =SUMIFS(Movements!$I:$I,Movements!$G:$G,$J$3,Movements!$B:$B,$C17,Movements!$A:$A,Stocks!E$1)+SUMIFS(Movements!$I:$I,Movements!$G:$G,$J$6,Movements!$B:$B,$C17,Movements!$A:$A,Stocks!E$1)+SUMIFS(Movements!$I:$I,Movements!$G:$G,$J$7,Movements!$B:$B,$C17,Movements!$A:$A,Stocks!E$1)+SUMIFS(Movements!$I:$I,Movements!$G:$G,$J$8,Movements!$B:$B,$C17,Movements!$A:$A,Stocks!E$1) -> 0 | F17: =SUMIFS(Movements!$I:$I,Movements!$G:$G,$J$3,Movements!$B:$B,$C17,Movements!$A:$A,Stocks!F$1)+SUMIFS(Movements!$I:$I,Movements!$G:$G,$J$6,Movements!$B:$B,$C17,Movements!$A:$A,Stocks!F$1)+SUMIFS(Movements!$I:$I,Movements!$G:$G,$J$7,Movements!$B:$B,$C17,Movements!$A:$A,Stocks!F$1)+SUMIFS(Movements!$I:$I,Movements!$G:$G,$J$8,Movements!$B:$B,$C17,Movements!$A:$A,Stocks!F$1) -> -500 | G17: =SUMIFS(Movements!$I:$I,Movements!$G:$G,$J$3,Movements!$B:$B,$C17,Movements!$A:$A,Stocks!G$1)+SUMIFS(Movements!$I:$I,Movements!$G:$G,$J$6,Movements!$B:$B,$C17,Movements!$A:$A,Stocks!G$1)+SUMIFS(Movements!$I:$I,Movements!$G:$G,$J$7,Movements!$B:$B,$C17,Movements!$A:$A,Stocks!G$1)+SUMIFS(Movements!$I:$I,Movements!$G:$G,$J$8,Movements!$B:$B,$C17,Movements!$A:$A,Stocks!G$1) -> -1300 | H17: =SUMIFS(Movements!$I:$I,Movements!$G:$G,$J$3,Movements!$B:$B,$C17,Movements!$A:$A,Stocks!H$1)+SUMIFS(Movements!$I:$I,Movements!$G:$G,$J$6,Movements!$B:$B,$C17,Movements!$A:$A,Stocks!H$1)+SUMIFS(Movements!$I:$I,Movements!$G:$G,$J$7,Movements!$B:$B,$C17,Movements!$A:$A,Stocks!H$1)+SUMIFS(Movements!$I:$I,Movements!$G:$G,$J$8,Movements!$B:$B,$C17,Movements!$A:$A,Stocks!H$1) -> -1003
C18: 867156 | D18: Chocolate mass | E18: =SUMIFS(Movements!$I:$I,Movements!$G:$G,$J$3,Movements!$B:$B,$C18,Movements!$A:$A,Stocks!E$1)+SUMIFS(Movements!$I:$I,Movements!$G:$G,$J$6,Movements!$B:$B,$C18,Movements!$A:$A,Stocks!E$1)+SUMIFS(Movements!$I:$I,Movements!$G:$G,$J$7,Movements!$B:$B,$C18,Movements!$A:$A,Stocks!E$1)+SUMIFS(Movements!$I:$I,Movements!$G:$G,$J$8,Movements!$B:$B,$C18,Movements!$A:$A,Stocks!E$1) -> 0 | F18: =SUMIFS(Movements!$I:$I,Movements!$G:$G,$J$3,Movements!$B:$B,$C18,Movements!$A:$A,Stocks!F$1)+SUMIFS(Movements!$I:$I,Movements!$G:$G,$J$6,Movements!$B:$B,$C18,Movements!$A:$A,Stocks!F$1)+SUMIFS(Movements!$I:$I,Movements!$G:$G,$J$7,Movements!$B:$B,$C18,Movements!$A:$A,Stocks!F$1)+SUMIFS(Movements!$I:$I,Movements!$G:$G,$J$8,Movements!$B:$B,$C18,Movements!$A:$A,Stocks!F$1) -> -948 | G18: =SUMIFS(Movements!$I:$I,Movements!$G:$G,$J$3,Movements!$B:$B,$C18,Movements!$A:$A,Stocks!G$1)+SUMIFS(Movements!$I:$I,Movements!$G:$G,$J$6,Movements!$B:$B,$C18,Movements!$A:$A,Stocks!G$1)+SUMIFS(Movements!$I:$I,Movements!$G:$G,$J$7,Movements!$B:$B,$C18,Movements!$A:$A,Stocks!G$1)+SUMIFS(Movements!$I:$I,Movements!$G:$G,$J$8,Movements!$B:$B,$C18,Movements!$A:$A,Stocks!G$1) -> -1454.4 | H18: =SUMIFS(Movements!$I:$I,Movements!$G:$G,$J$3,Movements!$B:$B,$C18,Movements!$A:$A,Stocks!H$1)+SUMIFS(Movements!$I:$I,Movements!$G:$G,$J$6,Movements!$B:$B,$C18,Movements!$A:$A,Stocks!H$1)+SUMIFS(Movements!$I:$I,Movements!$G:$G,$J$7,Movements!$B:$B,$C18,Movements!$A:$A,Stocks!H$1)+SUMIFS(Movements!$I:$I,Movements!$G:$G,$J$8,Movements!$B:$B,$C18,Movements!$A:$A,Stocks!H$1) -> -678.6
C19: 765190 | D19: Caramel | E19: =SUMIFS(Movements!$I:$I,Movements!$G:$G,$J$3,Movements!$B:$B,$C19,Movements!$A:$A,Stocks!E$1)+SUMIFS(Movements!$I:$I,Movements!$G:$G,$J$6,Movements!$B:$B,$C19,Movements!$A:$A,Stocks!E$1)+SUMIFS(Movements!$I:$I,Movements!$G:$G,$J$7,Movements!$B:$B,$C19,Movements!$A:$A,Stocks!E$1)+SUMIFS(Movements!$I:$I,Movements!$G:$G,$J$8,Movements!$B:$B,$C19,Movements!$A:$A,Stocks!E$1) -> 0 | F19: =SUMIFS(Movements!$I:$I,Movements!$G:$G,$J$3,Movements!$B:$B,$C19,Movements!$A:$A,Stocks!F$1)+SUMIFS(Movements!$I:$I,Movements!$G:$G,$J$6,Movements!$B:$B,$C19,Movements!$A:$A,Stocks!F$1)+SUMIFS(Movements!$I:$I,Movements!$G:$G,$J$7,Movements!$B:$B,$C19,Movements!$A:$A,Stocks!F$1)+SUMIFS(Movements!$I:$I,Movements!$G:$G,$J$8,Movements!$B:$B,$C19,Movements!$A:$A,Stocks!F$1) -> -151 | G19: =SUMIFS(Movements!$I:$I,Movements!$G:$G,$J$3,Movements!$B:$B,$C19,Movements!$A:$A,Stocks!G$1)+SUMIFS(Movements!$I:$I,Movements!$G:$G,$J$6,Movements!$B:$B,$C19,Movements!$A:$A,Stocks!G$1)+SUMIFS(Movements!$I:$I,Movements!$G:$G,$J$7,Movements!$B:$B,$C19,Movements!$A:$A,Stocks!G$1)+SUMIFS(Movements!$I:$I,Movements!$G:$G,$J$8,Movements!$B:$B,$C19,Movements!$A:$A,Stocks!G$1) -> -245.1 | H19: =SUMIFS(Movements!$I:$I,Movements!$G:$G,$J$3,Movements!$B:$B,$C19,Movements!$A:$A,Stocks!H$1)+SUMIFS(Movements!$I:$I,Movements!$G:$G,$J$6,Movements!$B:$B,$C19,Movements!$A:$A,Stocks!H$1)+SUMIFS(Movements!$I:$I,Movements!$G:$G,$J$7,Movements!$B:$B,$C19,Movements!$A:$A,Stocks!H$1)+SUMIFS(Movements!$I:$I,Movements!$G:$G,$J$8,Movements!$B:$B,$C19,Movements!$A:$A,Stocks!H$1) -> -101.9
C20: 657341 | D20: Raw Peanut | E20: =SUMIFS(Movements!$I:$I,Movements!$G:$G,$J$3,Movements!$B:$B,$C20,Movements!$A:$A,Stocks!E$1)+SUMIFS(Movements!$I:$I,Movements!$G:$G,$J$6,Movements!$B:$B,$C20,Movements!$A:$A,Stocks!E$1)+SUMIFS(Movements!$I:$I,Movements!$G:$G,$J$7,Movements!$B:$B,$C20,Movements!$A:$A,Stocks!E$1)+SUMIFS(Movements!$I:$I,Movements!$G:$G,$J$8,Movements!$B:$B,$C20,Movements!$A:$A,Stocks!E$1) -> 0 | F20: =SUMIFS(Movements!$I:$I,Movements!$G:$G,$J$3,Movements!$B:$B,$C20,Movements!$A:$A,Stocks!F$1)+SUMIFS(Movements!$I:$I,Movements!$G:$G,$J$6,Movements!$B:$B,$C20,Movements!$A:$A,Stocks!F$1)+SUMIFS(Movements!$I:$I,Movements!$G:$G,$J$7,Movements!$B:$B,$C20,Movements!$A:$A,Stocks!F$1)+SUMIFS(Movements!$I:$I,Movements!$G:$G,$J$8,Movements!$B:$B,$C20,Movements!$A:$A,Stocks!F$1) -> -122.6925 | G20: =SUMIFS(Movements!$I:$I,Movements!$G:$G,$J$3,Movements!$B:$B,$C20,Movements!$A:$A,Stocks!G$1)+SUMIFS(Movements!$I:$I,Movements!$G:$G,$J$6,Movements!$B:$B,$C20,Movements!$A:$A,Stocks!G$1)+SUMIFS(Movements!$I:$I,Movements!$G:$G,$J$7,Movements!$B:$B,$C20,Movements!$A:$A,Stocks!G$1)+SUMIFS(Movements!$I:$I,Movements!$G:$G,$J$8,Movements!$B:$B,$C20,Movements!$A:$A,Stocks!G$1) -> -250.8075 | H20: =SUMIFS(Movements!$I:$I,Movements!$G:$G,$J$3,Movements!$B:$B,$C20,Movements!$A:$A,Stocks!H$1)+SUMIFS(Movements!$I:$I,Movements!$G:$G,$J$6,Movements!$B:$B,$C20,Movements!$A:$A,Stocks!H$1)+SUMIFS(Movements!$I:$I,Movements!$G:$G,$J$7,Movements!$B:$B,$C20,Movements!$A:$A,Stocks!H$1)+SUMIFS(Movements!$I:$I,Movements!$G:$G,$J$8,Movements!$B:$B,$C20,Movements!$A:$A,Stocks!H$1) -> -116
C21: 876145 | D21: Fried Peanut | E21: =SUMIFS(Movements!$I:$I,Movements!$G:$G,$J$3,Movements!$B:$B,$C21,Movements!$A:$A,Stocks!E$1)+SUMIFS(Movements!$I:$I,Movements!$G:$G,$J$6,Movements!$B:$B,$C21,Movements!$A:$A,Stocks!E$1)+SUMIFS(Movements!$I:$I,Movements!$G:$G,$J$7,Movements!$B:$B,$C21,Movements!$A:$A,Stocks!E$1)+SUMIFS(Movements!$I:$I,Movements!$G:$G,$J$8,Movements!$B:$B,$C21,Movements!$A:$A,Stocks!E$1) -> 0 | F21: =SUMIFS(Movements!$I:$I,Movements!$G:$G,$J$3,Movements!$B:$B,$C21,Movements!$A:$A,Stocks!F$1)+SUMIFS(Movements!$I:$I,Movements!$G:$G,$J$6,Movements!$B:$B,$C21,Movements!$A:$A,Stocks!F$1)+SUMIFS(Movements!$I:$I,Movements!$G:$G,$J$7,Movements!$B:$B,$C21,Movements!$A:$A,Stocks!F$1)+SUMIFS(Movements!$I:$I,Movements!$G:$G,$J$8,Movements!$B:$B,$C21,Movements!$A:$A,Stocks!F$1) -> -104.55 | G21: =SUMIFS(Movements!$I:$I,Movements!$G:$G,$J$3,Movements!$B:$B,$C21,Movements!$A:$A,Stocks!G$1)+SUMIFS(Movements!$I:$I,Movements!$G:$G,$J$6,Movements!$B:$B,$C21,Movements!$A:$A,Stocks!G$1)+SUMIFS(Movements!$I:$I,Movements!$G:$G,$J$7,Movements!$B:$B,$C21,Movements!$A:$A,Stocks!G$1)+SUMIFS(Movements!$I:$I,Movements!$G:$G,$J$8,Movements!$B:$B,$C21,Movements!$A:$A,Stocks!G$1) -> -167 | H21: =SUMIFS(Movements!$I:$I,Movements!$G:$G,$J$3,Movements!$B:$B,$C21,Movements!$A:$A,Stocks!H$1)+SUMIFS(Movements!$I:$I,Movements!$G:$G,$J$6,Movements!$B:$B,$C21,Movements!$A:$A,Stocks!H$1)+SUMIFS(Movements!$I:$I,Movements!$G:$G,$J$7,Movements!$B:$B,$C21,Movements!$A:$A,Stocks!H$1)+SUMIFS(Movements!$I:$I,Movements!$G:$G,$J$8,Movements!$B:$B,$C21,Movements!$A:$A,Stocks!H$1) -> -143.5
C22: 560196 | D22: Biscuit | E22: =SUMIFS(Movements!$I:$I,Movements!$G:$G,$J$3,Movements!$B:$B,$C22,Movements!$A:$A,Stocks!E$1)+SUMIFS(Movements!$I:$I,Movements!$G:$G,$J$6,Movements!$B:$B,$C22,Movements!$A:$A,Stocks!E$1)+SUMIFS(Movements!$I:$I,Movements!$G:$G,$J$7,Movements!$B:$B,$C22,Movements!$A:$A,Stocks!E$1)+SUMIFS(Movements!$I:$I,Movements!$G:$G,$J$8,Movements!$B:$B,$C22,Movements!$A:$A,Stocks!E$1) -> 0 | F22: =SUMIFS(Movements!$I:$I,Movements!$G:$G,$J$3,Movements!$B:$B,$C22,Movements!$A:$A,Stocks!F$1)+SUMIFS(Movements!$I:$I,Movements!$G:$G,$J$6,Movements!$B:$B,$C22,Movements!$A:$A,Stocks!F$1)+SUMIFS(Movements!$I:$I,Movements!$G:$G,$J$7,Movements!$B:$B,$C22,Movements!$A:$A,Stocks!F$1)+SUMIFS(Movements!$I:$I,Movements!$G:$G,$J$8,Movements!$B:$B,$C22,Movements!$A:$A,Stocks!F$1) -> -340 | G22: =SUMIFS(Movements!$I:$I,Movements!$G:$G,$J$3,Movements!$B:$B,$C22,Movements!$A:$A,Stocks!G$1)+SUMIFS(Movements!$I:$I,Movements!$G:$G,$J$6,Movements!$B:$B,$C22,Movements!$A:$A,Stocks!G$1)+SUMIFS(Movements!$I:$I,Movements!$G:$G,$J$7,Movements!$B:$B,$C22,Movements!$A:$A,Stocks!G$1)+SUMIFS(Movements!$I:$I,Movements!$G:$G,$J$8,Movements!$B:$B,$C22,Movements!$A:$A,Stocks!G$1) -> -481 | H22: =SUMIFS(Movements!$I:$I,Movements!$G:$G,$J$3,Movements!$B:$B,$C22,Movements!$A:$A,Stocks!H$1)+SUMIFS(Movements!$I:$I,Movements!$G:$G,$J$6,Movements!$B:$B,$C22,Movements!$A:$A,Stocks!H$1)+SUMIFS(Movements!$I:$I,Movements!$G:$G,$J$7,Movements!$B:$B,$C22,Movements!$A:$A,Stocks!H$1)+SUMIFS(Movements!$I:$I,Movements!$G:$G,$J$8,Movements!$B:$B,$C22,Movements!$A:$A,Stocks!H$1) -> -98
B23: Closing stock | C23: 120301 | D23: Fint | E23: =E2+E9+E16 -> 0 | F23: =F2+F9+F16 -> 210 | G23: =G2+G9+G16 -> 100 | H23: =H2+H9+H16 -> 0
C24: 156212 | D24: Step | E24: =E3+E10+E17 -> 0 | F24: =F3+F10+F17 -> 500 | G24: =G3+G10+G17 -> 700 | H24: =H3+H10+H17 -> 0
C25: 867156 | D25: Chocolate mass | E25: =E4+E11+E18 -> 2481 | F25: =F4+F11+F18 -> 1933 | G25: =G4+G11+G18 -> 578.6 | H25: =H4+H11+H18 -> 0
C26: 765190 | D26: Caramel | E26: =E5+E12+E19 -> 198 | F26: =F5+F12+F19 -> 247 | G26: =G5+G12+G19 -> 51.9 | H26: =H5+H12+H19 -> 0
C27: 657341 | D27: Raw Peanut | E27: =E6+E13+E20 -> 89.5 | F27: =F6+F13+F20 -> 266.8075 | G27: =G6+G13+G20 -> 66 | H27: =H6+H13+H20 -> 0
C28: 876145 | D28: Fried Peanut | E28: =E7+E14+E21 -> 0 | F28: =F7+F14+F21 -> 5.45 | G28: =G7+G14+G21 -> 43.5 | H28: =H7+H14+H21 -> 0
C29: 560196 | D29: Biscuit | E29: =E8+E15+E22 -> 230 | F29: =F8+F15+F22 -> 390 | G29: =G8+G15+G22 -> 9 | H29: =H8+H15+H22 -> 0

Sheet Sales
A1: Movement type | B1: dispatch
A3: Sum of Quantity | C3: Month | G3: Actuals selling price
A4: Material | B4: Mat descr | C4: November | D4: December | E4: January | G4: Material | H4: Mat descr | I4: November | J4: December | K4: January
A5: 120301 | B5: Fint | C5: -300 | D5: -900 | E5: -800 | G5: 120301 | H5: Fint | I5: 59 | J5: 63 | K5: 65
A6: 156212 | B6: Step | C6: -500 | D6: -1300 | E6: -1000 | G6: 156212 | H6: Step | I6: 35 | J6: 25 | K6: 25
A7: Grand Total | C7: -800 | D7: -2200 | E7: -1800
A9: Revenue
A10: Material | B10: Mat descr | C10: November | D10: December | E10: January
A11: 120301 | B11: Fint | C11: =-C5*I5 -> 17700 | D11: =-D5*J5 -> 56700 | E11: =-E5*K5 -> 52000
A12: 156212 | B12: Step | C12: =-C6*I6 -> 17500 | D12: =-D6*J6 -> 32500 | E12: =-E6*K6 -> 25000
A13: TOTAL SALES | C13: =SUM(C11:C12) -> 35200 | D13: =SUM(D11:D12) -> 89200 | E13: =SUM(E11:E12) -> 77000

Sheet Purchases & PPV
A1: Movement type | B1: reception
A3: Sum of Quantity | C3: Month | H3: Std price | K3: Actual Purchasing price
A4: Material | B4: Mat descr | C4: October | D4: November | E4: December | F4: January | H4: 2022 | I4: 2023 | K4: October | L4: November | M4: December | N4: January
A5: 560196 | B5: Biscuit | C5: 230 | D5: 500 | E5: 100 | F5: 89 | H5: =VLOOKUP(A5,'list of materials'!A:E,5,0) -> 25 | I5: =VLOOKUP(A5,'list of materials'!A:F,6,0) -> 27 | K5: 27 | L5: 26 | M5: 28 | N5: 30
A6: 657341 | B6: Raw Peanut | C6: 89.5 | D6: 300 | E6: 50 | F6: 50 | H6: =VLOOKUP(A6,'list of materials'!A:E,5,0) -> 25 | I6: =VLOOKUP(A6,'list of materials'!A:F,6,0) -> 24 | K6: 25 | L6: 25 | M6: 23 | N6: 20
A7: 765190 | B7: Caramel | C7: 198 | D7: 200 | E7: 50 | F7: 50 | H7: =VLOOKUP(A7,'list of materials'!A:E,5,0) -> 15 | I7: =VLOOKUP(A7,'list of materials'!A:F,6,0) -> 16 | K7: 15 | L7: 15 | M7: 16 | N7: 17
A8: 867156 | B8: Chocolate mass | C8: 2481 | D8: 400 | E8: 100 | F8: 100 | H8: =VLOOKUP(A8,'list of materials'!A:E,5,0) -> 28 | I8: =VLOOKUP(A8,'list of materials'!A:F,6,0) -> 31 | K8: 30 | L8: 31 | M8: 32 | N8: 28
A9: Grand Total | C9: 2998.5 | D9: 1400 | E9: 300 | F9: 289
A11: Reception @ std price | K11: Total Cash outflow
A12: Material | B12: Mat descr | C12: October | D12: November | E12: December | F12: January | K12: October | L12: November | M12: December | N12: January
A13: 560196 | B13: Biscuit | C13: =C5*$H5 -> 5750 | D13: =D5*$H5 -> 12500 | E13: =E5*$H5 -> 2500 | F13: =F5*$I5 -> 2403 | K13: =C5*K5 -> 6210 | L13: =D5*L5 -> 13000 | M13: =E5*M5 -> 2800 | N13: =F5*N5 -> 2670
A14: 657341 | B14: Raw Peanut | C14: =C6*$H6 -> 2237.5 | D14: =D6*$H6 -> 7500 | E14: =E6*$H6 -> 1250 | F14: =F6*$I6 -> 1200 | K14: =C6*K6 -> 2237.5 | L14: =D6*L6 -> 7500 | M14: =E6*M6 -> 1150 | N14: =F6*N6 -> 1000
A15: 765190 | B15: Caramel | C15: =C7*$H7 -> 2970 | D15: =D7*$H7 -> 3000 | E15: =E7*$H7 -> 750 | F15: =F7*$I7 -> 800 | K15: =C7*K7 -> 2970 | L15: =D7*L7 -> 3000 | M15: =E7*M7 -> 800 | N15: =F7*N7 -> 850
A16: 867156 | B16: Chocolate mass | C16: =C8*$H8 -> 69468 | D16: =D8*$H8 -> 11200 | E16: =E8*$H8 -> 2800 | F16: =F8*$I8 -> 3100 | K16: =C8*K8 -> 74430 | L16: =D8*L8 -> 12400 | M16: =E8*M8 -> 3200 | N16: =F8*N8 -> 2800
C17: =SUM(C13:C16) -> 80425.5 | D17: =SUM(D13:D16) -> 34200 | E17: =SUM(E13:E16) -> 7300 | F17: =SUM(F13:F16) -> 7503 | K17: =SUM(K13:K16) -> 85847.5 | L17: =SUM(L13:L16) -> 35900 | M17: =SUM(M13:M16) -> 7950 | N17: =SUM(N13:N16) -> 7320
A18: PPV (purchase price variance)
A19: Material | B19: Mat descr | C19: October | D19: November | E19: December | F19: January
A20: 560196 | B20: Biscuit | C20: =C5*(K5-$H5) -> 460 | D20: =D5*(L5-$H5) -> 500 | E20: =E5*(M5-$H5) -> 300 | F20: =F5*(N5-$I5) -> 267
A21: 657341 | B21: Raw Peanut | C21: =C6*(K6-$H6) -> 0 | D21: =D6*(L6-$H6) -> 0 | E21: =E6*(M6-$H6) -> -100 | F21: =F6*(N6-$I6) -> -200
A22: 765190 | B22: Caramel | C22: =C7*(K7-$H7) -> 0 | D22: =D7*(L7-$H7) -> 0 | E22: =E7*(M7-$H7) -> 50 | F22: =F7*(N7-$I7) -> 50
A23: 867156 | B23: Chocolate mass | C23: =C8*(K8-$H8) -> 4962 | D23: =D8*(L8-$H8) -> 1200 | E23: =E8*(M8-$H8) -> 400 | F23: =F8*(N8-$I8) -> -300
C24: =SUM(C20:C23) -> 5422 | D24: =SUM(D20:D23) -> 1700 | E24: =SUM(E20:E23) -> 650 | F24: =SUM(F20:F23) -> -183

Sheet Stock reval
E1: October | F1: November | G1: December | H1: January | N1: October | O1: November | P1: December | Q1: January
A2: =VLOOKUP(C2,'list of materials'!A:C,3,0) -> FG | B2: Closing stock | C2: 120301 | D2: Fint | E2: =Stocks!E23 -> 0 | F2: =Stocks!F23 -> 210 | G2: =Stocks!G23 -> 100 | H2: =Stocks!H23 -> 0 | J2: =VLOOKUP(L2,'list of materials'!A:C,3,0) -> FG | K2: Std cost | L2: 120301 | M2: Fint | N2: =VLOOKUP($L2,'list of materials'!$A:$F,5,0) -> 27.24775 | O2: =VLOOKUP($L2,'list of materials'!$A:$F,5,0) -> 27.24775 | P2: =VLOOKUP($L2,'list of materials'!$A:$F,6,0) -> 29.2598 | Q2: =VLOOKUP($L2,'list of materials'!$A:$F,6,0) -> 29.2598
A3: =VLOOKUP(C3,'list of materials'!A:C,3,0) -> FG | C3: 156212 | D3: Step | E3: =Stocks!E24 -> 0 | F3: =Stocks!F24 -> 500 | G3: =Stocks!G24 -> 700 | H3: =Stocks!H24 -> 0 | J3: =VLOOKUP(L3,'list of materials'!A:C,3,0) -> FG | L3: 156212 | M3: Step | N3: =VLOOKUP($L3,'list of materials'!$A:$F,5,0) -> 25.945 | O3: =VLOOKUP($L3,'list of materials'!$A:$F,5,0) -> 25.945 | P3: =VLOOKUP($L3,'list of materials'!$A:$F,6,0) -> 28.45 | Q3: =VLOOKUP($L3,'list of materials'!$A:$F,6,0) -> 28.45
A4: =VLOOKUP(C4,'list of materials'!A:C,3,0) -> RM | C4: 867156 | D4: Chocolate mass | E4: =Stocks!E25 -> 2481 | F4: =Stocks!F25 -> 1933 | G4: =Stocks!G25 -> 578.6 | H4: =Stocks!H25 -> 0 | J4: =VLOOKUP(L4,'list of materials'!A:C,3,0) -> RM | L4: 867156 | M4: Chocolate mass | N4: =VLOOKUP($L4,'list of materials'!$A:$F,5,0) -> 28 | O4: =VLOOKUP($L4,'list of materials'!$A:$F,5,0) -> 28 | P4: =VLOOKUP($L4,'list of materials'!$A:$F,6,0) -> 31 | Q4: =VLOOKUP($L4,'list of materials'!$A:$F,6,0) -> 31
A5: =VLOOKUP(C5,'list of materials'!A:C,3,0) -> RM | C5: 765190 | D5: Caramel | E5: =Stocks!E26 -> 198 | F5: =Stocks!F26 -> 247 | G5: =Stocks!G26 -> 51.9 | H5: =Stocks!H26 -> 0 | J5: =VLOOKUP(L5,'list of materials'!A:C,3,0) -> RM | L5: 765190 | M5: Caramel | N5: =VLOOKUP($L5,'list of materials'!$A:$F,5,0) -> 15 | O5: =VLOOKUP($L5,'list of materials'!$A:$F,5,0) -> 15 | P5: =VLOOKUP($L5,'list of materials'!$A:$F,6,0) -> 16 | Q5: =VLOOKUP($L5,'list of materials'!$A:$F,6,0) -> 16
A6: =VLOOKUP(C6,'list of materials'!A:C,3,0) -> RM | C6: 657341 | D6: Raw Peanut | E6: =Stocks!E27 -> 89.5 | F6: =Stocks!F27 -> 266.8075 | G6: =Stocks!G27 -> 66 | H6: =Stocks!H27 -> 0 | J6: =VLOOKUP(L6,'list of materials'!A:C,3,0) -> RM | L6: 657341 | M6: Raw Peanut | N6: =VLOOKUP($L6,'list of materials'!$A:$F,5,0) -> 25 | O6: =VLOOKUP($L6,'list of materials'!$A:$F,5,0) -> 25 | P6: =VLOOKUP($L6,'list of materials'!$A:$F,6,0) -> 24 | Q6: =VLOOKUP($L6,'list of materials'!$A:$F,6,0) -> 24
